#include<iostream>
using namespace std;
void Xtest(int test)
{
	cout<<"inside Xtest is "<<test<<endl;
	if(test)throw test;
}
int main()
{
	cout<<"Start"<<endl;
	try
	{
		cout<<"inside try block"<<endl;
		Xtest(0);
		Xtest(1);
		Xtest(2);
	}
	catch(int i)
	{
		cout<<"Caught an exception --- value is"<<i<<endl;
	}
	cout<<"End"<<endl;
	return 0;
}
